Traceback (most recent call last):
  File "/opt/homebrew/lib/python3.10/site-packages/jupyter_cache/executors/utils.py", line 51, in single_nb_execution
    executenb(
  File "/opt/homebrew/lib/python3.10/site-packages/nbclient/client.py", line 1204, in execute
    return NotebookClient(nb=nb, resources=resources, km=km, **kwargs).execute()
  File "/opt/homebrew/lib/python3.10/site-packages/nbclient/util.py", line 84, in wrapped
    return just_run(coro(*args, **kwargs))
  File "/opt/homebrew/lib/python3.10/site-packages/nbclient/util.py", line 62, in just_run
    return loop.run_until_complete(coro)
  File "/opt/homebrew/Cellar/python@3.10/3.10.8/Frameworks/Python.framework/Versions/3.10/lib/python3.10/asyncio/base_events.py", line 649, in run_until_complete
    return future.result()
  File "/opt/homebrew/lib/python3.10/site-packages/nbclient/client.py", line 663, in async_execute
    await self.async_execute_cell(
  File "/opt/homebrew/lib/python3.10/site-packages/nbclient/client.py", line 965, in async_execute_cell
    await self._check_raise_for_error(cell, cell_index, exec_reply)
  File "/opt/homebrew/lib/python3.10/site-packages/nbclient/client.py", line 862, in _check_raise_for_error
    raise CellExecutionError.from_cell_and_msg(cell, exec_reply_content)
nbclient.exceptions.CellExecutionError: An error occurred while executing the following cell:
------------------
from pytorch_lightning import Trainer
from contextualized.dags.torch_notmad.callbacks import *
from contextualized.dags.torch_notmad.torch_notmad import NOTMAD_model
from contextualized.dags.torch_notmad.datamodules import CX_DataModule
from contextualized.dags.torch_notmad.baselines import BayesianNetwork, GroupedNetworks, project_all, dag_pred, mse_loss
from contextualized.dags.notmad_helpers.simulation import simulate_linear_sem
from sklearn.model_selection import train_test_split

dag_pred_torch = dag_pred
dag_pred = lambda a, b: dag_pred_torch(torch.Tensor(a), torch.Tensor(b))
------------------

[0;31m---------------------------------------------------------------------------[0m
[0;31mModuleNotFoundError[0m                       Traceback (most recent call last)
Cell [0;32mIn [14], line 2[0m
[1;32m      1[0m [38;5;28;01mfrom[39;00m [38;5;21;01mpytorch_lightning[39;00m [38;5;28;01mimport[39;00m Trainer
[0;32m----> 2[0m [38;5;28;01mfrom[39;00m [38;5;21;01mcontextualized[39;00m[38;5;21;01m.[39;00m[38;5;21;01mdags[39;00m[38;5;21;01m.[39;00m[38;5;21;01mtorch_notmad[39;00m[38;5;21;01m.[39;00m[38;5;21;01mcallbacks[39;00m [38;5;28;01mimport[39;00m [38;5;241m*[39m
[1;32m      3[0m [38;5;28;01mfrom[39;00m [38;5;21;01mcontextualized[39;00m[38;5;21;01m.[39;00m[38;5;21;01mdags[39;00m[38;5;21;01m.[39;00m[38;5;21;01mtorch_notmad[39;00m[38;5;21;01m.[39;00m[38;5;21;01mtorch_notmad[39;00m [38;5;28;01mimport[39;00m NOTMAD_model
[1;32m      4[0m [38;5;28;01mfrom[39;00m [38;5;21;01mcontextualized[39;00m[38;5;21;01m.[39;00m[38;5;21;01mdags[39;00m[38;5;21;01m.[39;00m[38;5;21;01mtorch_notmad[39;00m[38;5;21;01m.[39;00m[38;5;21;01mdatamodules[39;00m [38;5;28;01mimport[39;00m CX_DataModule

[0;31mModuleNotFoundError[0m: No module named 'contextualized.dags.torch_notmad'
ModuleNotFoundError: No module named 'contextualized.dags.torch_notmad'

